<?xml version="1.0" ?>
<!-- =================================================================================== -->
<!-- |    This document was autogenerated by xacro from gp25.xacro                     | -->
<!-- |    EDITING THIS FILE BY HAND IS NOT RECOMMENDED                                 | -->
<!-- =================================================================================== -->
<robot name="motoman_gp25">
    <!-- link list -->
    <link name="base_link">
        <visual>
            <geometry>
                <mesh filename="package://motoman_gp25_support/meshes/visual/base_link.stl" />
            </geometry>
            <material name="">
                <color rgba="0.12941176470588237 0.14901960784313725 0.7490196078431373 1.0" />
            </material>
        </visual>
        <collision>
            <geometry>
                <mesh filename="package://motoman_gp25_support/meshes/collision/base_link.stl" />
            </geometry>
            <surface>
                <contact>
                    <ode>
                        <min_depth>0.001</min_depth>
                    </ode>
                </contact>
            </surface>
        </collision>
        <inertial>
            <mass value="0.1" />
            <origin xyz="0 0 0" rpy="0 0 0" />
            <inertia ixx="0.03" iyy="0.03" izz="0.03" ixy="0.0" ixz="0.0" iyz="0.0" />
        </inertial>
    </link>
    <link name="link_1_s">
        <visual>
            <geometry>
                <mesh filename="package://motoman_gp25_support/meshes/visual/link_1_s.stl" />
            </geometry>
            <material name="">
                <color rgba="0.12941176470588237 0.14901960784313725 0.7490196078431373 1.0" />
            </material>
        </visual>
        <collision>
            <geometry>
                <mesh filename="package://motoman_gp25_support/meshes/collision/link_1_s.stl" />
            </geometry>
        </collision>
        <inertial>
            <mass value="0.1" />
            <origin xyz="0 0 0" rpy="0 0 0" />
            <inertia ixx="0.03" iyy="0.03" izz="0.03" ixy="0.0" ixz="0.0" iyz="0.0" />
        </inertial>
    </link>
    <link name="link_2_l">
        <visual>
            <geometry>
                <mesh filename="package://motoman_gp25_support/meshes/visual/link_2_l.stl" />
            </geometry>
            <material name="">
                <color rgba="0.12941176470588237 0.14901960784313725 0.7490196078431373 1.0" />
            </material>
        </visual>
        <collision>
            <geometry>
                <mesh filename="package://motoman_gp25_support/meshes/collision/link_2_l.stl" />
            </geometry>
        </collision>
        <inertial>
            <mass value="0.1" />
            <origin xyz="0 0 0" rpy="0 0 0" />
            <inertia ixx="0.03" iyy="0.03" izz="0.03" ixy="0.0" ixz="0.0" iyz="0.0" />
        </inertial>
    </link>
    <link name="link_3_u">
        <visual>
            <geometry>
                <mesh filename="package://motoman_gp25_support/meshes/visual/link_3_u.stl" />
            </geometry>
            <material name="">
                <color rgba="0.12941176470588237 0.14901960784313725 0.7490196078431373 1.0" />
            </material>
        </visual>
        <collision>
            <geometry>
                <mesh filename="package://motoman_gp25_support/meshes/collision/link_3_u.stl" />
            </geometry>
        </collision>
        <inertial>
            <mass value="0.1" />
            <origin xyz="0 0 0" rpy="0 0 0" />
            <inertia ixx="0.03" iyy="0.03" izz="0.03" ixy="0.0" ixz="0.0" iyz="0.0" />
        </inertial>
    </link>
    <link name="link_4_r">
        <visual>
            <geometry>
                <mesh filename="package://motoman_gp25_support/meshes/visual/link_4_r.stl" />
            </geometry>
            <material name="">
                <color rgba="0.12941176470588237 0.14901960784313725 0.7490196078431373 1.0" />
            </material>
        </visual>
        <collision>
            <geometry>
                <mesh filename="package://motoman_gp25_support/meshes/collision/link_4_r.stl" />
            </geometry>
        </collision>
        <inertial>
            <mass value="0.1" />
            <origin xyz="0 0 0" rpy="0 0 0" />
            <inertia ixx="0.03" iyy="0.03" izz="0.03" ixy="0.0" ixz="0.0" iyz="0.0" />
        </inertial>
    </link>
    <link name="link_5_b">
        <visual>
            <geometry>
                <mesh filename="package://motoman_gp25_support/meshes/visual/link_5_b.stl" />
            </geometry>
            <material name="">
                <color rgba="0.12941176470588237 0.14901960784313725 0.7490196078431373 1.0" />
            </material>
        </visual>
        <collision>
            <geometry>
                <mesh filename="package://motoman_gp25_support/meshes/collision/link_5_b.stl" />
            </geometry>
        </collision>
        <inertial>
            <mass value="0.1" />
            <origin xyz="0 0 0" rpy="0 0 0" />
            <inertia ixx="0.03" iyy="0.03" izz="0.03" ixy="0.0" ixz="0.0" iyz="0.0" />
        </inertial>
    </link>
    <link name="link_6_t">
        <visual>
            <geometry>
                <mesh filename="package://motoman_gp25_support/meshes/visual/link_6_t.stl" />
            </geometry>
            <material name="">
                <color rgba="0.12941176470588237 0.14901960784313725 0.7490196078431373 1.0" />
            </material>
        </visual>
        <collision>
            <geometry>
                <mesh filename="package://motoman_gp25_support/meshes/collision/link_6_t.stl" />
            </geometry>
        </collision>
        <inertial>
            <mass value="0.1" />
            <origin xyz="0 0 0" rpy="0 0 0" />
            <inertia ixx="0.03" iyy="0.03" izz="0.03" ixy="0.0" ixz="0.0" iyz="0.0" />
        </inertial>
    </link>
    <link name="tool0" />
    
    <!-- end of link list -->
    <!-- joint list -->
    <joint name="joint_1_s" type="revolute">
        <parent link="base_link" />
        <child link="link_1_s" />
        <origin rpy="0 0 0" xyz="0 0 0.505" />
        <axis xyz="0 0 1" />
        <limit effort="3087" lower="-3.141592653589793" upper="3.141592653589793" velocity="3.6651914291880923" />
    </joint>
    <joint name="joint_2_l" type="revolute">
        <parent link="link_1_s" />
        <child link="link_2_l" />
        <origin rpy="0 0 0" xyz="0.150 0 0" />
        <axis xyz="0 1 0" />
        <limit effort="3087" lower="-1.8325957145940461" upper="2.705260340591211" velocity="3.6651914291880923" />
    </joint>
    <joint name="joint_3_u" type="revolute">
        <parent link="link_2_l" />
        <child link="link_3_u" />
        <origin rpy="0 0 0" xyz="0 0 0.760" />
        <axis xyz="0 -1 0" />
        <limit effort="926.1" lower="-1.5009831567151235" upper="2.792526803190927" velocity="4.625122517784973" />
    </joint>
    <joint name="joint_4_r" type="revolute">
        <parent link="link_3_u" />
        <child link="link_4_r" />
        <origin rpy="0 0 0" xyz="0 0 0.200" />
        <axis xyz="-1 0 0" />
        <limit effort="88.2" lower="-3.490658503988659" upper="3.490658503988659" velocity="7.3303828583761845" />
    </joint>
    <joint name="joint_5_b" type="revolute">
        <parent link="link_4_r" />
        <child link="link_5_b" />
        <origin rpy="0 0 0" xyz="0.795 0 0" />
        <axis xyz="0 -1 0" />
        <limit effort="70.56" lower="-2.705260340591211" upper="2.6179938779914944" velocity="7.3303828583761845" />
    </joint>
    <joint name="joint_6_t" type="revolute">
        <parent link="link_5_b" />
        <child link="link_6_t" />
        <origin rpy="0 0 0" xyz="0 0 0" />
        <axis xyz="-1 0 0" />
        <limit effort="50.31" lower="-7.941248096574199" upper="7.941248096574199" velocity="15.446163880149816" />
    </joint>
    <joint name="joint_6_t-tool0" type="fixed">
        <origin rpy="3.1415926 -1.570796 0" xyz="0.100 0 0" />
        <parent link="link_6_t" />
        <child link="tool0" />
    </joint>
    <!-- 报错新增 -->
    <link name="world"> 
    </link>
    <joint name="fixed_base_joint" type="fixed">
        <parent link="world"/>
        <child link="base_link"/>
    </joint>
    <!-- end of joint list -->
    <!-- ROS base_link to Robot Manufacturer World Coordinates transform -->
    <link name="base" />
    <joint name="base_link-base" type="fixed">
        <origin rpy="0 0 0" xyz="0 0 0.505" />
        <parent link="base_link" />
        <child link="base" />
    </joint>
    <transmission name="trans_joint_1_s">
        <type>transmission_interface/SimpleTransmission</type>
        <joint name="joint_1_s">
            <hardwareInterface>hardware_interface/PositionJointInterface</hardwareInterface>
        </joint>
        <actuator name="joint_1_s_motor">
            <hardwareInterface>hardware_interface/PositionJointInterface</hardwareInterface>
            <mechanicalReduction>1</mechanicalReduction>
        </actuator>
    </transmission>
    <transmission name="trans_joint_2_l">
        <type>transmission_interface/SimpleTransmission</type>
        <joint name="joint_2_l">
            <hardwareInterface>hardware_interface/PositionJointInterface</hardwareInterface>
        </joint>
        <actuator name="joint_2_l_motor">
            <hardwareInterface>hardware_interface/PositionJointInterface</hardwareInterface>
            <mechanicalReduction>1</mechanicalReduction>
        </actuator>
    </transmission>
    <transmission name="trans_joint_3_u">
        <type>transmission_interface/SimpleTransmission</type>
        <joint name="joint_3_u">
            <hardwareInterface>hardware_interface/PositionJointInterface</hardwareInterface>
        </joint>
        <actuator name="joint_3_u_motor">
            <hardwareInterface>hardware_interface/PositionJointInterface</hardwareInterface>
            <mechanicalReduction>1</mechanicalReduction>
        </actuator>
    </transmission>
    <transmission name="trans_joint_4_r">
        <type>transmission_interface/SimpleTransmission</type>
        <joint name="joint_4_r">
            <hardwareInterface>hardware_interface/PositionJointInterface</hardwareInterface>
        </joint>
        <actuator name="joint_4_r_motor">
            <hardwareInterface>hardware_interface/PositionJointInterface</hardwareInterface>
            <mechanicalReduction>1</mechanicalReduction>
        </actuator>
    </transmission>
    <transmission name="trans_joint_5_b">
        <type>transmission_interface/SimpleTransmission</type>
        <joint name="joint_5_b">
            <hardwareInterface>hardware_interface/PositionJointInterface</hardwareInterface>
        </joint>
        <actuator name="joint_5_b_motor">
            <hardwareInterface>hardware_interface/PositionJointInterface</hardwareInterface>
            <mechanicalReduction>1</mechanicalReduction>
        </actuator>
    </transmission>
    <transmission name="trans_joint_6_t">
        <type>transmission_interface/SimpleTransmission</type>
        <joint name="joint_6_t">
            <hardwareInterface>hardware_interface/PositionJointInterface</hardwareInterface>
        </joint>
        <actuator name="joint_6_t_motor">
            <hardwareInterface>hardware_interface/PositionJointInterface</hardwareInterface>
            <mechanicalReduction>1</mechanicalReduction>
        </actuator>
    </transmission>
    <!-- 报错新增  filename="libgazebo_ros_control.so"-->
    <gazebo>
        <plugin name="gazebo_ros_control"  filename="libgazebo_ros_control.so">
            <robotNamespace>/</robotNamespace>
        </plugin>
    </gazebo>
</robot>

